<?xml version="1.0" encoding="utf-8" ?>
<!-- =================================================================================== -->
<!-- |    This document was autogenerated by xacro from /home/bnguye14/Desktop/ROS/rosowi/src/owi/model/owi.xacro | -->
<!-- |    EDITING THIS FILE BY HAND IS NOT RECOMMENDED                                 | -->
<!-- =================================================================================== -->
<robot name="owi">
    <!-- robot model  -->
    <link name="base_link">
        <visual>
            <geometry>
                <cylinder length="0.05" radius="0.05" />
            </geometry>
            <origin rpy="0 0 0" xyz="0 0 0.025" />
        </visual>
        <visual>
            <geometry>
                <box size="0.15 0.08 0.05" />
            </geometry>
            <origin rpy="0 0 0" xyz="-0.1 0 0.025" />
        </visual>
        <collision>
            <geometry>
                <cylinder length="0.05" radius="0.05" />
            </geometry>
            <origin rpy="0 0 0" xyz="0 0 0.025" />
        </collision>
        <collision>
            <geometry>
                <box size="0.15 0.08 0.05" />
            </geometry>
            <origin rpy="0 0 0" xyz="-0.1 0 0.025" />
        </collision>
        
<inertial>
            <mass value="0.1" />
            <inertia ixx="0.03" iyy="0.03" izz="0.03" ixy="0.0" ixz="0.0" iyz="0.0" />
        </inertial>

    </link>
    <joint name="jointLink1" type="revolute">
        <parent link="base_link" />
        <child link="Link1" />
        <axis xyz="0 0 1" />
        <origin rpy="0.0 0 0" xyz="0 0 0.065" />
        <limit effort="100" lower="-1.57079632679" upper="1.57079632679" velocity="1" />
    </joint>
    <link name="Link1" />
    <joint name="jointLink2" type="revolute">
        <parent link="Link1" />
        <child link="Link2" />
        <axis xyz="0 0 1" />
        <origin rpy="1.57079632679 0 0" xyz="0 0 0" />
        <limit effort="100" lower="0.0" upper="3.14159265359" velocity="1" />
    </joint>
    <link name="Link2">
        <!-- elbow -->
        <visual>
            <geometry>
                <cylinder length="0.03" radius="0.015" />
            </geometry>
            <origin rpy="0 0 0" xyz="0 0 0" />
        </visual>
        <collision>
            <geometry>
                <cylinder length="0.03" radius="0.015" />
            </geometry>
            <origin rpy="0 0 0" xyz="0 0 0" />
        </collision>
        <!-- axial -->
        <visual>
            <geometry>
                <box size="0.015 0.015 0" />
            </geometry>
            <origin rpy="0 0 0" xyz="0 0 0.0" />
        </visual>
        <collision>
            <geometry>
                <box size="0.015 0.015 0.0" />
            </geometry>
            <origin rpy="0 0 0" xyz="0 0 0.0" />
        </collision>
        <!-- radial -->
        <visual>
            <geometry>
                <box size="0.0425 0.015 0.015" />
            </geometry>
            <origin rpy="0 0 0" xyz="0.0425 0 0" />
        </visual>
        <collision>
            <geometry>
                <box size="0.0425 0.015 0.015" />
            </geometry>
            <origin rpy="0 0 0" xyz="0.0425 0 0" />
        </collision>
        
<inertial>
            <mass value="0.1" />
            <inertia ixx="0.03" iyy="0.03" izz="0.03" ixy="0.0" ixz="0.0" iyz="0.0" />
        </inertial>

    </link>
    <joint name="jointLink3" type="revolute">
        <parent link="Link2" />
        <child link="Link3" />
        <axis xyz="0 0 1" />
        <origin rpy="0.0 0 0" xyz="0.085 0 0" />
        <limit effort="100" lower="-2.35619449019" upper="2.35619449019" velocity="1" />
    </joint>
    <link name="Link3">
        <!-- elbow -->
        <visual>
            <geometry>
                <cylinder length="0.03" radius="0.015" />
            </geometry>
            <origin rpy="0 0 0" xyz="0 0 0" />
        </visual>
        <collision>
            <geometry>
                <cylinder length="0.03" radius="0.015" />
            </geometry>
            <origin rpy="0 0 0" xyz="0 0 0" />
        </collision>
        <!-- axial -->
        <visual>
            <geometry>
                <box size="0.015 0.015 0" />
            </geometry>
            <origin rpy="0 0 0" xyz="0 0 0.0" />
        </visual>
        <collision>
            <geometry>
                <box size="0.015 0.015 0.0" />
            </geometry>
            <origin rpy="0 0 0" xyz="0 0 0.0" />
        </collision>
        <!-- radial -->
        <visual>
            <geometry>
                <box size="0.0575 0.015 0.015" />
            </geometry>
            <origin rpy="0 0 0" xyz="0.0575 0 0" />
        </visual>
        <collision>
            <geometry>
                <box size="0.0575 0.015 0.015" />
            </geometry>
            <origin rpy="0 0 0" xyz="0.0575 0 0" />
        </collision>
        
<inertial>
            <mass value="0.1" />
            <inertia ixx="0.03" iyy="0.03" izz="0.03" ixy="0.0" ixz="0.0" iyz="0.0" />
        </inertial>

    </link>
    <joint name="jointLink4" type="revolute">
        <parent link="Link3" />
        <child link="Link4" />
        <axis xyz="0 0 1" />
        <origin rpy="0.0 0 0" xyz="0.115 0 0" />
        <limit effort="100" lower="-1.0471975512" upper="1.0471975512" velocity="1" />
    </joint>
    <link name="Link4">
        <!-- elbow -->
        <visual>
            <geometry>
                <cylinder length="0.03" radius="0.015" />
            </geometry>
            <origin rpy="0 0 0" xyz="0 0 0" />
        </visual>
        <collision>
            <geometry>
                <cylinder length="0.03" radius="0.015" />
            </geometry>
            <origin rpy="0 0 0" xyz="0 0 0" />
        </collision>
        <!-- axial -->
        <visual>
            <geometry>
                <box size="0.015 0.015 0" />
            </geometry>
            <origin rpy="0 0 0" xyz="0 0 0.0" />
        </visual>
        <collision>
            <geometry>
                <box size="0.015 0.015 0.0" />
            </geometry>
            <origin rpy="0 0 0" xyz="0 0 0.0" />
        </collision>
        <!-- radial -->
        <visual>
            <geometry>
                <box size="0.03 0.015 0.015" />
            </geometry>
            <origin rpy="0 0 0" xyz="0.03 0 0" />
        </visual>
        <collision>
            <geometry>
                <box size="0.03 0.015 0.015" />
            </geometry>
            <origin rpy="0 0 0" xyz="0.03 0 0" />
        </collision>
        
<inertial>
            <mass value="0.1" />
            <inertia ixx="0.03" iyy="0.03" izz="0.03" ixy="0.0" ixz="0.0" iyz="0.0" />
        </inertial>

    </link>
    <joint name="jointRgripper" type="revolute">
        <parent link="Link4" />
        <child link="Rgripper" />
        <axis xyz="0 0 1" />
        <origin rpy="1.57079632679 0 0" xyz="0.06 0 0.005" />
        <limit effort="100" lower="0.0" upper="1.57079632679" velocity="1" />
    </joint>
    <joint name="jointLgripper" type="revolute">
        <parent link="Link4" />
        <child link="Lgripper" />
        <axis xyz="0 0 1" />
        <origin rpy="-1.57079632679 0 0" xyz="0.06 0 -0.005" />
        <limit effort="100" lower="0.0" upper="1.57079632679" velocity="1" />
        <mimic joint="jointRgripper" />
    </joint>
    <link name="Rgripper">
        <!-- elbow -->
        <visual>
            <geometry>
                <cylinder length="0.01" radius="0.005" />
            </geometry>
            <origin rpy="0 0 0" xyz="0 0 0" />
        </visual>
        <collision>
            <geometry>
                <cylinder length="0.01" radius="0.005" />
            </geometry>
            <origin rpy="0 0 0" xyz="0 0 0" />
        </collision>
        <!-- axial -->
        <visual>
            <geometry>
                <box size="0.005 0.005 0" />
            </geometry>
            <origin rpy="0 0 0" xyz="0 0 0.0" />
        </visual>
        <collision>
            <geometry>
                <box size="0.005 0.005 0.0" />
            </geometry>
            <origin rpy="0 0 0" xyz="0 0 0.0" />
        </collision>
        <!-- radial -->
        <visual>
            <geometry>
                <box size="0.015 0.005 0.005" />
            </geometry>
            <origin rpy="0 0 0" xyz="0.015 0 0" />
        </visual>
        <collision>
            <geometry>
                <box size="0.015 0.005 0.005" />
            </geometry>
            <origin rpy="0 0 0" xyz="0.015 0 0" />
        </collision>
        
<inertial>
            <mass value="0.1" />
            <inertia ixx="0.03" iyy="0.03" izz="0.03" ixy="0.0" ixz="0.0" iyz="0.0" />
        </inertial>

    </link>
    <link name="Lgripper">
        <!-- elbow -->
        <visual>
            <geometry>
                <cylinder length="0.01" radius="0.005" />
            </geometry>
            <origin rpy="0 0 0" xyz="0 0 0" />
        </visual>
        <collision>
            <geometry>
                <cylinder length="0.01" radius="0.005" />
            </geometry>
            <origin rpy="0 0 0" xyz="0 0 0" />
        </collision>
        <!-- axial -->
        <visual>
            <geometry>
                <box size="0.005 0.005 0" />
            </geometry>
            <origin rpy="0 0 0" xyz="0 0 0.0" />
        </visual>
        <collision>
            <geometry>
                <box size="0.005 0.005 0.0" />
            </geometry>
            <origin rpy="0 0 0" xyz="0 0 0.0" />
        </collision>
        <!-- radial -->
        <visual>
            <geometry>
                <box size="0.015 0.005 0.005" />
            </geometry>
            <origin rpy="0 0 0" xyz="0.015 0 0" />
        </visual>
        <collision>
            <geometry>
                <box size="0.015 0.005 0.005" />
            </geometry>
            <origin rpy="0 0 0" xyz="0.015 0 0" />
        </collision>
        
<inertial>
            <mass value="0.1" />
            <inertia ixx="0.03" iyy="0.03" izz="0.03" ixy="0.0" ixz="0.0" iyz="0.0" />
        </inertial>

    </link>
    
<transmission name="trans_jointLink1">
        <type>transmission_interface/SimpleTransmission</type>
        <joint name="jointLink1">
            <hardwareInterface>hardware_interface/EffortJointInterface</hardwareInterface>
        </joint>
        <actuator name="jointLink1_motor">
            <hardwareInterface>hardware_interface/EffortJointInterface</hardwareInterface>
            <mechanicalReduction>1</mechanicalReduction>
        </actuator>
    </transmission>
    <transmission name="trans_jointLink2">
        <type>transmission_interface/SimpleTransmission</type>
        <joint name="jointLink2">
            <hardwareInterface>hardware_interface/EffortJointInterface</hardwareInterface>
        </joint>
        <actuator name="jointLink2_motor">
            <hardwareInterface>hardware_interface/EffortJointInterface</hardwareInterface>
            <mechanicalReduction>1</mechanicalReduction>
        </actuator>
    </transmission>
    <transmission name="trans_jointLink3">
        <type>transmission_interface/SimpleTransmission</type>
        <joint name="jointLink3">
            <hardwareInterface>hardware_interface/EffortJointInterface</hardwareInterface>
        </joint>
        <actuator name="jointLink3_motor">
            <hardwareInterface>hardware_interface/EffortJointInterface</hardwareInterface>
            <mechanicalReduction>1</mechanicalReduction>
        </actuator>
    </transmission>
    <transmission name="trans_jointLink4">
        <type>transmission_interface/SimpleTransmission</type>
        <joint name="jointLink4">
            <hardwareInterface>hardware_interface/EffortJointInterface</hardwareInterface>
        </joint>
        <actuator name="jointLink4_motor">
            <hardwareInterface>hardware_interface/EffortJointInterface</hardwareInterface>
            <mechanicalReduction>1</mechanicalReduction>
        </actuator>
    </transmission>
    <transmission name="trans_jointRgripper">
        <type>transmission_interface/SimpleTransmission</type>
        <joint name="jointRgripper">
            <hardwareInterface>hardware_interface/EffortJointInterface</hardwareInterface>
        </joint>
        <actuator name="jointRgripper_motor">
            <hardwareInterface>hardware_interface/EffortJointInterface</hardwareInterface>
            <mechanicalReduction>1</mechanicalReduction>
        </actuator>
    </transmission>
    <transmission name="trans_jointLgripper">
        <type>transmission_interface/SimpleTransmission</type>
        <joint name="jointLgripper">
            <hardwareInterface>hardware_interface/EffortJointInterface</hardwareInterface>
        </joint>
        <actuator name="jointLgripper_motor">
            <hardwareInterface>hardware_interface/EffortJointInterface</hardwareInterface>
            <mechanicalReduction>1</mechanicalReduction>
        </actuator>
    </transmission>
    <gazebo>
        <plugin name="gazebo_ros_control" filename="libgazebo_ros_control.so">
            <robotNamespace>/</robotNamespace>
        </plugin>
    </gazebo>
</robot>