<?xml version="1.0" encoding="utf-8"?>
<!-- =================================================================================== -->
<!-- |    This document was autogenerated by xacro from owi.xacro                      | -->
<!-- |    EDITING THIS FILE BY HAND IS NOT RECOMMENDED                                 | -->
<!-- =================================================================================== -->
<robot name="owi">
  <!-- robot model  -->
  <link name="base_link">
    <visual>
      <geometry>
        <cylinder length="0.05" radius="0.05"/>
      </geometry>
      <origin rpy="0 0 0" xyz="0 0 0.025"/>
    </visual>
    <visual>
      <geometry>
        <box size="0.15 0.08 0.05"/>
      </geometry>
      <origin rpy="0 0 0" xyz="-0.1 0 0.025"/>
    </visual>
    <collision>
      <geometry>
        <cylinder length="0.04" radius="0.05"/>
      </geometry>
      <origin rpy="0 0 0" xyz="0 0 0.025"/>
    </collision>
    <collision>
      <geometry>
        <box size="0.15 0.08 0.05"/>
      </geometry>
      <origin rpy="0 0 0" xyz="-0.1 0 0.025"/>
    </collision>
    <intnertial>
      <mass value="0.3"/>
      <inertia ixx="0.1" ixy="0.0" ixz="0.0" iyy="0.1" iyz="0.0" izz="0.1"/>
    </intnertial>
  </link>
  <joint name="jointLink1" type="revolute">
    <parent link="base_link"/>
    <child link="Link1"/>
    <axis xyz="0 0 1"/>
    <origin rpy="0.0 0 0" xyz="0 0 0.065"/>
    <limit effort="100" lower="-1.57079632679" upper="1.57079632679" velocity="1"/>
  </joint>
  <link name="Link1"/>
  <joint name="jointLink2" type="revolute">
    <parent link="Link1"/>
    <child link="Link2"/>
    <axis xyz="0 0 1"/>
    <origin rpy="1.57079632679 0 0" xyz="0 0 0"/>
    <limit effort="100" lower="0.0" upper="3.14159265359" velocity="1"/>
  </joint>
  <link name="Link2">
    <!-- elbow -->
    <visual>
      <geometry>
        <cylinder length="0.03" radius="0.015"/>
      </geometry>
      <origin rpy="0 0 0" xyz="0 0 0"/>
    </visual>
    <collision>
      <geometry>
        <cylinder length="0.03" radius="0.015"/>
      </geometry>
      <origin rpy="0 0 0" xyz="0 0 0"/>
    </collision>
    <!-- axial -->
    <visual>
      <geometry>
        <box size="0.015 0.015 0"/>
      </geometry>
      <origin rpy="0 0 0" xyz="0 0 0.0"/>
    </visual>
    <collision>
      <geometry>
        <box size="0.015 0.015 0.0"/>
      </geometry>
      <origin rpy="0 0 0" xyz="0 0 0.0"/>
    </collision>
    <!-- radial -->
    <visual>
      <geometry>
        <box size="0.0425 0.015 0.015"/>
      </geometry>
      <origin rpy="0 0 0" xyz="0.0425 0 0"/>
    </visual>
    <collision>
      <geometry>
        <box size="0.0425 0.015 0.015"/>
      </geometry>
      <origin rpy="0 0 0" xyz="0.0425 0 0"/>
    </collision>
    <intnertial>
      <mass value="0.1"/>
      <inertia ixx="0.033" ixy="0.0" ixz="0.0" iyy="0.033" iyz="0.0" izz="0.033"/>
    </intnertial>
  </link>
  <joint name="jointLink3" type="revolute">
    <parent link="Link2"/>
    <child link="Link3"/>
    <axis xyz="0 0 1"/>
    <origin rpy="0.0 0 0" xyz="0.085 0 0"/>
    <limit effort="100" lower="-2.35619449019" upper="2.35619449019" velocity="1"/>
  </joint>
  <link name="Link3">
    <!-- elbow -->
    <visual>
      <geometry>
        <cylinder length="0.03" radius="0.015"/>
      </geometry>
      <origin rpy="0 0 0" xyz="0 0 0"/>
    </visual>
    <collision>
      <geometry>
        <cylinder length="0.03" radius="0.015"/>
      </geometry>
      <origin rpy="0 0 0" xyz="0 0 0"/>
    </collision>
    <!-- axial -->
    <visual>
      <geometry>
        <box size="0.015 0.015 0"/>
      </geometry>
      <origin rpy="0 0 0" xyz="0 0 0.0"/>
    </visual>
    <collision>
      <geometry>
        <box size="0.015 0.015 0.0"/>
      </geometry>
      <origin rpy="0 0 0" xyz="0 0 0.0"/>
    </collision>
    <!-- radial -->
    <visual>
      <geometry>
        <box size="0.0575 0.015 0.015"/>
      </geometry>
      <origin rpy="0 0 0" xyz="0.0575 0 0"/>
    </visual>
    <collision>
      <geometry>
        <box size="0.0575 0.015 0.015"/>
      </geometry>
      <origin rpy="0 0 0" xyz="0.0575 0 0"/>
    </collision>
    <intnertial>
      <mass value="0.1"/>
      <inertia ixx="0.033" ixy="0.0" ixz="0.0" iyy="0.033" iyz="0.0" izz="0.033"/>
    </intnertial>
  </link>
  <joint name="jointLink4" type="revolute">
    <parent link="Link3"/>
    <child link="Link4"/>
    <axis xyz="0 0 1"/>
    <origin rpy="0.0 0 0" xyz="0.115 0 0"/>
    <limit effort="100" lower="-1.0471975512" upper="1.0471975512" velocity="1"/>
  </joint>
  <link name="Link4">
    <!-- elbow -->
    <visual>
      <geometry>
        <cylinder length="0.03" radius="0.015"/>
      </geometry>
      <origin rpy="0 0 0" xyz="0 0 0"/>
    </visual>
    <collision>
      <geometry>
        <cylinder length="0.03" radius="0.015"/>
      </geometry>
      <origin rpy="0 0 0" xyz="0 0 0"/>
    </collision>
    <!-- axial -->
    <visual>
      <geometry>
        <box size="0.015 0.015 0"/>
      </geometry>
      <origin rpy="0 0 0" xyz="0 0 0.0"/>
    </visual>
    <collision>
      <geometry>
        <box size="0.015 0.015 0.0"/>
      </geometry>
      <origin rpy="0 0 0" xyz="0 0 0.0"/>
    </collision>
    <!-- radial -->
    <visual>
      <geometry>
        <box size="0.03 0.015 0.015"/>
      </geometry>
      <origin rpy="0 0 0" xyz="0.03 0 0"/>
    </visual>
    <collision>
      <geometry>
        <box size="0.03 0.015 0.015"/>
      </geometry>
      <origin rpy="0 0 0" xyz="0.03 0 0"/>
    </collision>
    <intnertial>
      <mass value="0.1"/>
      <inertia ixx="0.033" ixy="0.0" ixz="0.0" iyy="0.033" iyz="0.0" izz="0.033"/>
    </intnertial>
  </link>
  <joint name="dummy" type="fixed">
    <parent link="Link4"/>
    <child link="grip_base"/>
    <origin rpy="0 0 0" xyz="0.06 0 0"/>
  </joint>
  <link name="grip_base">
    <visual>
      <geometry>
        <box size="0 0 0"/>
      </geometry>
      <origin rpy="0 0 0" xyz="0 0 0"/>
    </visual>
  </link>
  <joint name="jointRgripper" type="revolute">
    <parent link="grip_base"/>
    <child link="Rgripper"/>
    <axis xyz="0 0 1"/>
    <origin rpy="1.57079632679 0 0" xyz="0 0 0.006"/>
    <limit effort="100" lower="0.0" upper="1.57079632679" velocity="1"/>
  </joint>
  <joint name="jointLgripper" type="revolute">
    <parent link="grip_base"/>
    <child link="Lgripper"/>
    <axis xyz="0 0 1"/>
    <origin rpy="-1.57079632679 0 0" xyz="0 0 -0.006"/>
    <limit effort="100" lower="0.0" upper="1.57079632679" velocity="1"/>
    <mimic joint="jointRgripper"/>
  </joint>
  <link name="Rgripper">
    <!-- elbow -->
    <visual>
      <geometry>
        <cylinder length="0.01" radius="0.005"/>
      </geometry>
      <origin rpy="0 0 0" xyz="0 0 0"/>
    </visual>
    <collision>
      <geometry>
        <cylinder length="0.01" radius="0.005"/>
      </geometry>
      <origin rpy="0 0 0" xyz="0 0 0"/>
    </collision>
    <!-- axial -->
    <visual>
      <geometry>
        <box size="0.005 0.005 0"/>
      </geometry>
      <origin rpy="0 0 0" xyz="0 0 0.0"/>
    </visual>
    <collision>
      <geometry>
        <box size="0.005 0.005 0.0"/>
      </geometry>
      <origin rpy="0 0 0" xyz="0 0 0.0"/>
    </collision>
    <!-- radial -->
    <visual>
      <geometry>
        <box size="0.015 0.005 0.005"/>
      </geometry>
      <origin rpy="0 0 0" xyz="0.015 0 0"/>
    </visual>
    <collision>
      <geometry>
        <box size="0.015 0.005 0.005"/>
      </geometry>
      <origin rpy="0 0 0" xyz="0.015 0 0"/>
    </collision>
    <intnertial>
      <mass value="0.1"/>
      <inertia ixx="0.033" ixy="0.0" ixz="0.0" iyy="0.033" iyz="0.0" izz="0.033"/>
    </intnertial>
  </link>
  <link name="Lgripper">
    <!-- elbow -->
    <visual>
      <geometry>
        <cylinder length="0.01" radius="0.005"/>
      </geometry>
      <origin rpy="0 0 0" xyz="0 0 0"/>
    </visual>
    <collision>
      <geometry>
        <cylinder length="0.01" radius="0.005"/>
      </geometry>
      <origin rpy="0 0 0" xyz="0 0 0"/>
    </collision>
    <!-- axial -->
    <visual>
      <geometry>
        <box size="0.005 0.005 0"/>
      </geometry>
      <origin rpy="0 0 0" xyz="0 0 0.0"/>
    </visual>
    <collision>
      <geometry>
        <box size="0.005 0.005 0.0"/>
      </geometry>
      <origin rpy="0 0 0" xyz="0 0 0.0"/>
    </collision>
    <!-- radial -->
    <visual>
      <geometry>
        <box size="0.015 0.005 0.005"/>
      </geometry>
      <origin rpy="0 0 0" xyz="0.015 0 0"/>
    </visual>
    <collision>
      <geometry>
        <box size="0.015 0.005 0.005"/>
      </geometry>
      <origin rpy="0 0 0" xyz="0.015 0 0"/>
    </collision>
    <intnertial>
      <mass value="0.1"/>
      <inertia ixx="0.033" ixy="0.0" ixz="0.0" iyy="0.033" iyz="0.0" izz="0.033"/>
    </intnertial>
  </link>
</robot>

